Workbook

Sheet Firebase
A1: Setting up Firebase | B1: Scribe link
A3: 1. Create the Firebase project | B3: https://scribehow.com/viewer/Create_a_Firebase_Project__iojkdmbnTdiIcW2nEi8RSA
A4: 2. Enable User login Authentication | B4: https://scribehow.com/viewer/Enable_EmailPassword_Authentication_in_Firebase__lhnJ_dNQQtW9t4Q3xcg2dQ
A5: 3. Setting up the database | B5: https://scribehow.com/viewer/Create_a_Firestore_Database_in_Firebase__SaiKXmaaTZiS2spcdUNBeQ
A6: 4. Add your Firebase config to the React app folder | B6: https://scribehow.com/viewer/Create_env_file__iEYivBJpR7yYQXH8b7KJZg
A7: =LEFT(D92,FIND("=",D92))&E16 -> VITE_FIREBASE_API_KEY="AIzaSyCJHBlqy9mCvOq2YfodUkAXGc94he5gK-I"
A8: =LEFT(D93,FIND("=",D93))&E17 -> VITE_FIREBASE_AUTH_DOMAIN="trouidees-6798f.firebaseapp.com"
A9: =LEFT(D94,FIND("=",D94))&E18 -> VITE_FIREBASE_PROJECT_ID="trouidees-6798f"
A10: =LEFT(D95,FIND("=",D95))&E69 -> VITE_FIREBASE_STORAGE_BUCKET="trouidees-6798f.firebasestorage.app"
A11: =LEFT(D96,FIND("=",D96))&E70 -> VITE_FIREBASE_MESSAGING_SENDER_ID="73054714346"
A12: =LEFT(D97,FIND("=",D97))&E71 -> VITE_FIREBASE_APP_ID="1:73054714346:web:897ee5f366e7b82e11da93"
A13: =LEFT(D98,FIND("=",D98))&E72 -> VITE_FIREBASE_MEASUREMENT_ID="G-GYH226GVJQ"
A14: 5. Create the default React App on your local machine | B14: https://scribehow.com/viewer/Create_React_Files_in_IDE__UcHPaSbpT7OEDfEXdEUATQ
A15: Create all the defualt React files for me and start the local server. I want to develop a program that will be hosted on Firebase, I have already created the .env file with all the Firebase credentials, and created the database.
A16: 6. Get new database rules for firebase | B16: https://scribehow.com/viewer/Create_New_Rules_for_Firebase_Database__Xd1IBNfnTimr63GVFMuM5Q | D16: ='Firebase Cred Copy from Step 1'!A10 -> apiKey: "AIzaSyCJHBlqy9mCvOq2YfodUkAXGc94he5gK-I", | E16: =SUBSTITUTE(TRIM(MID(D16,FIND(":",D16)+1,100)),",","") -> "AIzaSyCJHBlqy9mCvOq2YfodUkAXGc94he5gK-I"
A17: 7. Change rules in Firebase | B17: https://scribehow.com/viewer/Update_Firestore_Security_Rules__NEeJ582eRHqPvcfkmBXGvw | D17: ='Firebase Cred Copy from Step 1'!A11 -> authDomain: "trouidees-6798f.firebaseapp.com", | E17: =SUBSTITUTE(TRIM(MID(D17,FIND(":",D17)+1,100)),",","") -> "trouidees-6798f.firebaseapp.com"
A18: 8. Add hosting on firebase | D18: ='Firebase Cred Copy from Step 1'!A12 -> projectId: "trouidees-6798f", | E18: =SUBSTITUTE(TRIM(MID(D18,FIND(":",D18)+1,100)),",","") -> "trouidees-6798f"
A44: 4. Restart your dev server if it’s running:
A46: cd app
A47: npm run dev
A48: 1. Open http://localhost:5173 (or whatever port Vite uses) and check:
A49: On the page you should see “Firebase app ID: \<your-app-id\>”.
A50: If it shows “Missing – check your .env”, the variables are not loaded correctly (double-check .env location and names).
A51: Now the React app is truly connected to Firebase and ready for Auth/Firestore.
A53: 5. Prepare Firebase Hosting on Google Cloud
A54: This part uses the Firebase CLI and will actually put your app on Google’s infrastructure.
A55: Install Firebase CLI (once on your machine)
A57: npm install -g firebase-tools
A58: Login and initialize hosting (from the app folder):
... A68: Build and deploy
D69: ='Firebase Cred Copy from Step 1'!A13 -> storageBucket: "trouidees-6798f.firebasestorage.app", | E69: =SUBSTITUTE(TRIM(MID(D69,FIND(":",D69)+1,100)),",","") -> "trouidees-6798f.firebasestorage.app"
A70: npm run build | D70: ='Firebase Cred Copy from Step 1'!A14 -> messagingSenderId: "73054714346", | E70: =SUBSTITUTE(TRIM(MID(D70,FIND(":",D70)+1,100)),",","") -> "73054714346"
A71: firebase deploy --only hosting | D71: ='Firebase Cred Copy from Step 1'!A15 -> appId: "1:73054714346:web:897ee5f366e7b82e11da93", | E71: =SUBSTITUTE(TRIM(MID(D71,FIND(":",D71)+1,100)),",","") -> "1:73054714346:web:897ee5f366e7b82e11da93"
A72: After that: | D72: ='Firebase Cred Copy from Step 1'!A16 -> measurementId: "G-GYH226GVJQ" | E72: =SUBSTITUTE(TRIM(MID(D72,FIND(":",D72)+1,100)),",","") -> "G-GYH226GVJQ"
A73: Firebase will show a Hosting URL where your React app is live on Google Cloud.
D92: VITE_FIREBASE_API_KEY=your-api-key
D93: VITE_FIREBASE_AUTH_DOMAIN=your-project-id.firebaseapp.com
D94: VITE_FIREBASE_PROJECT_ID=your-project-id
D95: VITE_FIREBASE_STORAGE_BUCKET=your-project-id.appspot.com
D96: VITE_FIREBASE_MESSAGING_SENDER_ID=your-messaging-sender-id
...

Sheet Firebase Cred Copy from Step 1
A1: // Import the functions you need from the SDKs you need
A2: import { initializeApp } from "firebase/app";
A3: import { getAnalytics } from "firebase/analytics";
A4: // TODO: Add SDKs for Firebase products that you want to use
A5: // https://firebase.google.com/docs/web/setup#available-libraries
A7: // Your web app's Firebase configuration
A8: // For Firebase JS SDK v7.20.0 and later, measurementId is optional
A9: const firebaseConfig = {
A10: apiKey: "AIzaSyCJHBlqy9mCvOq2YfodUkAXGc94he5gK-I",
A11: authDomain: "trouidees-6798f.firebaseapp.com",
A12: projectId: "trouidees-6798f",
A13: storageBucket: "trouidees-6798f.firebasestorage.app",
... A21: const analytics = getAnalytics(app);

Sheet First IDE Prompts
A2: 1 | B2: Test User create
B3: Go to Firebase and authentication and create one user for every role you need
B4: For example Admin@speccon.co.za, systemuser1@test.co.za
A6: 2 | B6: Users Login
B7: Setup login for users to either use email and password I created or the microsoft exchange login we setup
A9: 3 | B9: Admin role
B10: Create the following options for the admin user:
B11: Add the admin functions for the admin role. First one is user management. See a list features and roles. Roles should be on top, and then admin can tick boxes on what should be available for each user
A13: 4 | B13: Take the applicable brand guide text, and put into a text file and put that into your project files
B14: Use the brand guide text file (Insert path, for example "C:\Users\Asus\OneDrive - Speccon Holdings (Pty) Ltd\Software Development\Projects v2\Performance Management\SpecCon Brand Guide - Text Version.txt"), and make sure the program looks like the brand guide specifies
B15: - Headers must be on top
B16: - Profile icon must be on top right, and applicable role for user. Don’t show user email or the word "profile"
B17: - Notification icon must be top right for all system notifications
B18: - New releases star icone where we will list new features and big fixes. And if somebody clicks on it, show detail of what is released
A20: 5 | B20: Seed data
B21: if it’s a prototyoe system, then create seeddata, which can be changed if people used it to reset to to ensure the system can be tested with live data

Sheet Deploy
A1: Rules | B1: firebase deploy --only firestore:rules | E1: npx playwright test | F1: Runs the end-to-end tests.
A2: Login | B2: firebase login --reauth | E2: npx playwright test --ui | F2: Starts the interactive UI mode.
E3: npx playwright test --project=chromium | F3: Runs the tests only on Desktop Chrome.
E4: npx playwright test example | F4: Runs the tests in a specific file.
E5: npx playwright test --debug | F5: Runs the tests in debug mode.
E6: npx playwright codegen | F6: Auto generate tests with Codegen.

Sheet Trouidees Brand Guide
A1: 1. Brand Overview
A3: Name: Trou Idees
A4: Tagline: Your partner in wedding planning
A6: Core purpose:
A7: To guide and inspire couples – from engagement, through wedding planning, into marriage and everyday lifestyle.
A9: Brand promise:
A11: You don’t have to go through the planning and emotions of your wedding day and marriage alone – Trou Idees walks the journey with you like a trusted friend.
A15: 2. Brand Essence
A17: 2.1 Mission
A19: Help couples create a beautiful, meaningful wedding day.
A21: Encourage couples to invest more in their marriage than only their wedding day, with God at the center.
A23: 2.2 Values
... A115: Suggested core palette for a romantic, faith-rooted wedding brand:
A117: Role | B117: Name | C117: Hex | D117: Typical use
A118: Primary dark | B118: Charcoal | C118: #191919 | D118: Main text, icons, button text.
A119: Light background | B119: Soft Ivory | C119: #FFF8F2 | D119: Page backgrounds, sections, documents.
A120: Romantic accent | B120: Blush Rose | C120: #F9E3E8 | D120: Buttons, highlights, banners, subtle background blocks.
A121: Deep accent | B121: Deep Wine | C121: #5C1225 | D121: Important headings, strong CTAs, key highlights.
A122: Metallic accent | B122: Rose Gold | C122: #C48A7A | D122: Lines, borders, small decorative elements.
A124: Usage rules:
A126: Keep backgrounds soft and light, with charcoal for readability.
A128: Use blush and rose gold as accents, not as the main colour everywhere.
A130: Use Deep Wine for high-impact moments (important headings, CTA buttons).
A134: 4.3 Typography (Fonts)
A136: Concept: Elegant serif for headings + clean sans-serif for body text.
A138: 1. Headings (H1–H3):
A142: Recommended: Playfair Display or Cormorant Garamond
A144: Weight: Semi-bold/Bold
A146: Use for titles, quotes, and hero text.
A148: 2. Body text:
A152: Recommended: Lato, Open Sans, or Montserrat
... A364: #WeddingInspiration

Sheet Speccon Brand Guide
A1: ================================================================================
A2: SPECCON HOLDINGS BRAND IDENTITY GUIDE
A3: October 2025
A4: ================================================================================
A6: Prepared by NOMANSLAND
A8: ================================================================================
A9: VISION
A10: ================================================================================
A12: To be South Africa's leading Opportunity Ecosystem — pioneering growth,
A13: transforming lives, and enabling success through fearless innovation, belief,
A14: and client-centred partnerships.
A16: ================================================================================
... A253: DO NOT:
A254: {=- Omit the icon (the SC monogram must always be present)} -> #NAME?
A255: {=- Rearrange the logo elements} -> #NAME?
A256: - Alter the colour (do not change to red or other colours)
A257: - Alter the type/font
A258: - Tilt or rotate the logo
A259: - Alter or distort the icon
A261: ================================================================================
A262: COLOUR PALETTE
A263: ================================================================================
A265: PRIMARY COLOURS
A266: -------------------------------------------------------------------------------
A268: BLUE (Primary Brand Colour)
A269: Hex: #12265E
A270: RGB: 18, 38, 94
... A308: abcdefghijklmnopqrstuvwxyz
A309: 1234567890
A312: SECONDARY TYPEFACE - LIMITED AESTHETIC USAGE
A313: -------------------------------------------------------------------------------
A315: Times New Roman
A316: Weights: Regular, Bold
A318: Character Set:
A319: ABCDEFGHIJKLMNOPQRSTUVWXYZ
A320: abcdefghijklmnopqrstuvwxyz
A321: 1234567890
A323: ================================================================================
A324: PHRASE BANK
A325: ================================================================================
...

Sheet Academy Brand Guide
A1: ================================================================================
A2: SPECCON ACADEMY BRAND GUIDE
A3: November 2025
A4: ================================================================================
A6: TABLE OF CONTENTS
A7: -----------------
A8: 1. Brand Overview
A9: 2. Colour Palette
A10: 3. Typography
A11: 4. Logo Usage
A12: 5. Imagery Direction
A13: 6. Layout & Graphic Devices
... A101: abcdefghijklmnopqrstuvwxyz
A102: 1234567890
A104: ROBOTO (Wide/Body Usage)
A105: Weights: Regular, Bold, Thin, Light
A106: Use for: Body copy, subheadings, UI elements, general text
A107: Character: Clean, readable, versatile
A109: ABCDEFGHJIKLMNOPQRSTUVWXYZ
A110: abcdefghjiklmnopqrstuvwxyz
A111: 1234567890
A113: TYPOGRAPHY GUIDELINES
A114: ---------------------
A115: • Headlines: Harabara - bold and energetic, always legible
A116: • Body text: Roboto Regular or Light
A117: • Emphasis: Roboto Bold
A118: • Avoid overly corporate or cluttered text layouts
A119: • Keep text hierarchy clear and consistent
A122: ================================================================================
A123: 4. LOGO USAGE
A124: ================================================================================
A126: LOGO DESCRIPTION
A127: ----------------
... A364: Warm, clear, helpful, South African English, supportive
